Workbook

Sheet Aug-Apr, 2023
G1: 2022 | AU1: 2023
B2: Cookstoves First Phase Delivery | G2: Aug | O2: September | W2: October | AE2: Nov | AM2: December | AU2: January | BC2: February | BK2: March | BS2: April | CA2: May | CI2: June | CQ2: July | CY2: Augast | DG2: september | DO2: October | DW2: novermber | EE2: December
B3: Member | C3: Coop name | D3: Number of people in the household | E3: Monthly household income | F3: Number of meals per person per day | G3: Firewood consumption foraged (kg/month) | H3: Firewood consumption bought(kg/month) | I3: Charcoal consumption (kg/month) | J3: Pellets consumption (Kg/month | K3: Cost of firewood in-kind (RWF/month) | L3: Cost of firewood spent (RWF/month) | M3: Cost of charcoal (RWF/month) | N3: Cost of Pellets (RWF/month) | O3: Firewood consumption foraged (kg/month) | P3: Firewood consumption bought(kg/month) | Q3: Charcoal consumption (kg/month) | R3: Pellets Consumption (Kg/month | S3: Cost of firewood in-kind (RWF/month) | T3: Cost of firewood spent (RWF/month) | U3: Cost of charcoal (RWF/month) | V3: Cost of Pellets (RWF/month) | W3: Firewood consumption foraged (kg/month) | X3: Firewood consumption bought(kg/month) | Y3: Charcoal consumption (kg/month) | Z3: Pellets consumption (Kg/month | AA3: Cost of firewood in-kind (RWF/month) | AB3: Cost of firewood spent (RWF/month) | AC3: Cost of charcoal (RWF/month) | AD3: Cost of Pellets (RWF/month) | AE3: Firewood consumption foraged (kg/month) | AF3: Firewood consumption bought(kg/month) | AG3: Charcoal consumption (kg/month) | AH3: Pellets consumption (Kg/month | AI3: Cost of firewood in-kind (RWF/month) | AJ3: Cost of firewood spent (RWF/month) | AK3: Cost of charcoal (RWF/month) | AL3: Cost of Pellets (RWF/month) | AM3: Firewood consumption foraged (kg/month) | AN3: Firewood consumption bought(kg/month) | AO3: Charcoal consumption (kg/month) | AP3: Pellets consumption (Kg/month | AQ3: Cost of firewood in-kind (RWF/month) | AR3: Cost of firewood spent (RWF/month) | AS3: Cost of charcoal (RWF/month) | AT3: Cost of Pellets (RWF/month) | AU3: Firewood consumption foraged (kg/month) | AV3: Firewood consumption bought(kg/month) | AW3: Charcoal consumption (kg/month) | AX3: Pellets consumption (Kg/month | AY3: Cost of firewood in-kind (RWF/month) | AZ3: Cost of firewood spent (RWF/month) | BA3: Cost of charcoal (RWF/month) | BB3: Cost of Pellets (RWF/month) | BC3: Firewood consumption foraged (kg/month) | BD3: Firewood consumption bought(kg/month) | BE3: Charcoal consumption (kg/month) | BF3: Pellets consumption (Kg/month | BG3: Cost of firewood in-kind (RWF/month) | BH3: Cost of firewood spent (RWF/month) | BI3: Cost of charcoal (RWF/month) | BJ3: Cost of Pellets (RWF/month) | BK3: Firewood consumption foraged (kg/month) | BL3: Firewood consumption bought(kg/month) | BM3: Charcoal consumption (kg/month) | BN3: Pellets consumption (Kg/month | BO3: Cost of firewood in-kind (RWF/month) | BP3: Cost of firewood spent (RWF/month) | BQ3: Cost of charcoal (RWF/month) | BR3: Cost of Pellets (RWF/month) | BS3: Firewood consumption foraged (kg/month) | BT3: Firewood consumption bought(kg/month) | BU3: Charcoal consumption (kg/month) | BV3: Pellets consumption (Kg/month | BW3: Cost of firewood in-kind (RWF/month) | BX3: Cost of firewood spent (RWF/month) | BY3: Cost of charcoal (RWF/month) | BZ3: Cost of Pellets (RWF/month) | CA3: Firewood consumption foraged (kg/month) | CB3: Firewood consumption bought(kg/month) | CC3: Charcoal consumption (kg/month) | CD3: Pellets consumption (Kg/month | CE3: Cost of firewood in-kind (RWF/month) | CF3: Cost of firewood spent (RWF/month) | CG3: Cost of charcoal (RWF/month) | CH3: Cost of Pellets (RWF/month) | CI3: Firewood consumption foraged (kg/month) | CJ3: Firewood consumption bought(kg/month) | CK3: Charcoal consumption (kg/month) | CL3: Pellets consumption (Kg/month | CM3: Cost of firewood in-kind (RWF/month) | CN3: Cost of firewood spent (RWF/month) | CO3: Cost of charcoal (RWF/month) | CP3: Cost of Pellets (RWF/month) | CQ3: Firewood consumption foraged (kg/month) | CR3: Firewood consumption bought(kg/month) | CS3: Charcoal consumption (kg/month) | CT3: Pellets consumption (Kg/month | CU3: Cost of firewood in-kind (RWF/month) | CV3: Cost of firewood spent (RWF/month) | CW3: Cost of charcoal (RWF/month) | CX3: Cost of Pellets (RWF/month) | CY3: Firewood consumption foraged (kg/month) | CZ3: Firewood consumption bought(kg/month) | DA3: Charcoal consumption (kg/month) | DB3: Pellets consumption (Kg/month | DC3: Cost of firewood in-kind (RWF/month) | DD3: Cost of firewood spent (RWF/month) | DE3: Cost of charcoal (RWF/month) | DF3: Cost of Pellets (RWF/month) | DG3: Firewood consumption foraged (kg/month) | DH3: Firewood consumption bought(kg/month) | DI3: Charcoal consumption (kg/month) | DJ3: Pellets consumption (Kg/month | DK3: Cost of firewood in-kind (RWF/month) | DL3: Cost of firewood spent (RWF/month) | DM3: Cost of charcoal (RWF/month) | DN3: Cost of Pellets (RWF/month) | DO3: Firewood consumption foraged (kg/month) | DP3: Firewood consumption bought(kg/month) | DQ3: Charcoal consumption (kg/month) | DR3: Pellets consumption (Kg/month | DS3: Cost of firewood in-kind (RWF/month) | DT3: Cost of firewood spent (RWF/month) | DU3: Cost of charcoal (RWF/month) | DV3: Cost of Pellets (RWF/month) | DW3: Firewood consumption foraged (kg/month) | DX3: Firewood consumption bought(kg/month) | DY3: Charcoal consumption (kg/month) | DZ3: Pellets consumption (Kg/month | EA3: Cost of firewood in-kind (RWF/month) | EB3: Cost of firewood spent (RWF/month) | EC3: Cost of charcoal (RWF/month) | ED3: Cost of Pellets (RWF/month) | EE3: Firewood consumption foraged (kg/month) | EF3: Firewood consumption bought(kg/month) | EG3: Charcoal consumption (kg/month) | EH3: Pellets consumption (Kg/month | EI3: Cost of firewood in-kind (RWF/month) | EJ3: Cost of firewood spent (RWF/month) | EK3: Cost of charcoal (RWF/month) | EL3: Cost of Pellets (RWF/month)
A4: 1 | B4: Agnes MUSABYEYEZU | G4: 47 | H4: 0 | I4: 0 | J4: 20 | K4: =G4*100 -> 4700 | L4: =H4*100 -> 0 | M4: =I4*300 -> 0 | N4: =J4*300 -> 6000 | O4: 48 | P4: 0 | Q4: 0 | R4: 18 | S4: =O4*100 -> 4800 | T4: =P4*100 -> 0 | U4: =Q4*300 -> 0 | V4: =R4*300 -> 5400 | W4: 50 | X4: 0 | Y4: 0 | Z4: 19 | AA4: =W4*100 -> 5000 | AB4: =X4*100 -> 0 | AC4: =Y4*300 -> 0 | AD4: =Z4*300 -> 5700 | AE4: 50 | AF4: 0 | AG4: 0 | AH4: 19 | AI4: =AE4*100 -> 5000 | AJ4: =AF4*100 -> 0 | AK4: =AG4*300 -> 0 | AL4: =AH4*300 -> 5700 | AM4: 52 | AN4: 0 | AO4: 0 | AP4: 20 | AQ4: =AM4*100 -> 5200 | AR4: =AN4*100 -> 0 | AS4: =AO4*300 -> 0 | AT4: =AP4*300 -> 6000 | AU4: 52 | AV4: 0 | AW4: 0 | AX4: 20 | AY4: =AU4*100 -> 5200 | AZ4: =AV4*100 -> 0 | BA4: =AW4*300 -> 0 | BB4: =AX4*300 -> 6000 | BC4: 52 | BD4: 0 | BE4: 0 | BF4: 20 | BG4: =BC4*100 -> 5200 | BH4: =BD4*100 -> 0 | BI4: =BE4*300 -> 0 | BJ4: =BF4*300 -> 6000 | BK4: 52 | BL4: 0 | BM4: 0 | BN4: 20 | BO4: =BK4*100 -> 5200 | BP4: =BL4*100 -> 0 | BQ4: =BM4*300 -> 0 | BR4: =BN4*300 -> 6000 | BS4: 55 | BT4: 0 | BU4: 0 | BV4: 20 | BW4: =BS4*100 -> 5500 | BX4: =BT4*100 -> 0 | BY4: =BU4*300 -> 0 | BZ4: =BV4*300 -> 6000
A5: 2 | B5: Alice MUKAMISHA | G5: 50 | H5: 0 | I5: 0 | J5: 5 | K5: =G5*100 -> 5000 | L5: =H5*100 -> 0 | M5: =I5*300 -> 0 | N5: =J5*300 -> 1500 | O5: 50 | P5: 0 | Q5: 0 | R5: 10 | S5: =O5*100 -> 5000 | T5: =P5*100 -> 0 | U5: =Q5*300 -> 0 | V5: =R5*300 -> 3000 | W5: 48 | X5: 0 | Y5: 0 | Z5: 11 | AA5: =W5*100 -> 4800 | AB5: =X5*100 -> 0 | AC5: =Y5*300 -> 0 | AD5: =Z5*300 -> 3300 | AE5: 50 | AF5: 0 | AG5: 0 | AH5: 12 | AI5: =AE5*100 -> 5000 | AJ5: =AF5*100 -> 0 | AK5: =AG5*300 -> 0 | AL5: =AH5*300 -> 3600 | AM5: 48 | AN5: 0 | AO5: 0 | AP5: 10 | AQ5: =AM5*100 -> 4800 | AR5: =AN5*100 -> 0 | AS5: =AO5*300 -> 0 | AT5: =AP5*300 -> 3000 | AU5: 48 | AV5: 0 | AW5: 0 | AX5: 12 | AY5: =AU5*100 -> 4800 | AZ5: =AV5*100 -> 0 | BA5: =AW5*300 -> 0 | BB5: =AX5*300 -> 3600 | BC5: 48 | BD5: 0 | BE5: 0 | BF5: 12 | BG5: =BC5*100 -> 4800 | BH5: =BD5*100 -> 0 | BI5: =BE5*300 -> 0 | BJ5: =BF5*300 -> 3600 | BK5: 48 | BL5: 0 | BM5: 0 | BN5: 12 | BO5: =BK5*100 -> 4800 | BP5: =BL5*100 -> 0 | BQ5: =BM5*300 -> 0 | BR5: =BN5*300 -> 3600 | BS5: 52 | BT5: 0 | BU5: 0 | BV5: 15 | BW5: =BS5*100 -> 5200 | BX5: =BT5*100 -> 0 | BY5: =BU5*300 -> 0 | BZ5: =BV5*300 -> 4500
A6: 3 | B6: Alphonsine MUKARUGINA | G6: 35 | H6: 0 | I6: 0 | J6: 20 | K6: =G6*100 -> 3500 | L6: =H6*100 -> 0 | M6: =I6*300 -> 0 | N6: =J6*300 -> 6000 | O6: 55 | P6: 0 | Q6: 0 | R6: 20 | S6: =O6*100 -> 5500 | T6: =P6*100 -> 0 | U6: =Q6*300 -> 0 | V6: =R6*300 -> 6000 | W6: 50 | X6: 0 | Y6: 0 | Z6: 18 | AA6: =W6*100 -> 5000 | AB6: =X6*100 -> 0 | AC6: =Y6*300 -> 0 | AD6: =Z6*300 -> 5400 | AE6: 48 | AF6: 0 | AG6: 0 | AH6: 11 | AI6: =AE6*100 -> 4800 | AJ6: =AF6*100 -> 0 | AK6: =AG6*300 -> 0 | AL6: =AH6*300 -> 3300 | AM6: 40 | AN6: 0 | AO6: 0 | AP6: 20 | AQ6: =AM6*100 -> 4000 | AR6: =AN6*100 -> 0 | AS6: =AO6*300 -> 0 | AT6: =AP6*300 -> 6000 | AU6: 42 | AV6: 0 | AW6: 0 | AX6: 20 | AY6: =AU6*100 -> 4200 | AZ6: =AV6*100 -> 0 | BA6: =AW6*300 -> 0 | BB6: =AX6*300 -> 6000 | BC6: 44 | BD6: 0 | BE6: 0 | BF6: 20 | BG6: =BC6*100 -> 4400 | BH6: =BD6*100 -> 0 | BI6: =BE6*300 -> 0 | BJ6: =BF6*300 -> 6000 | BK6: 44 | BL6: 0 | BM6: 0 | BN6: 20 | BO6: =BK6*100 -> 4400 | BP6: =BL6*100 -> 0 | BQ6: =BM6*300 -> 0 | BR6: =BN6*300 -> 6000 | BS6: 46 | BT6: 0 | BU6: 0 | BV6: 20 | BW6: =BS6*100 -> 4600 | BX6: =BT6*100 -> 0 | BY6: =BU6*300 -> 0 | BZ6: =BV6*300 -> 6000
A7: 4 | B7: Anathalia MUKANKUSI | G7: 42 | H7: 0 | I7: 0 | J7: 10 | K7: =G7*100 -> 4200 | L7: =H7*100 -> 0 | M7: =I7*300 -> 0 | N7: =J7*300 -> 3000 | O7: 40 | P7: 0 | Q7: 0 | R7: 10 | S7: =O7*100 -> 4000 | T7: =P7*100 -> 0 | U7: =Q7*300 -> 0 | V7: =R7*300 -> 3000 | W7: 45 | X7: 0 | Y7: 0 | Z7: 13 | AA7: =W7*100 -> 4500 | AB7: =X7*100 -> 0 | AC7: =Y7*300 -> 0 | AD7: =Z7*300 -> 3900 | AE7: 61 | AF7: 0 | AG7: 0 | AH7: 18 | AI7: =AE7*100 -> 6100 | AJ7: =AF7*100 -> 0 | AK7: =AG7*300 -> 0 | AL7: =AH7*300 -> 5400 | AM7: 61 | AN7: 0 | AO7: 0 | AP7: 8 | AQ7: =AM7*100 -> 6100 | AR7: =AN7*100 -> 0 | AS7: =AO7*300 -> 0 | AT7: =AP7*300 -> 2400 | AU7: 60 | AV7: 0 | AW7: 0 | AX7: 12 | AY7: =AU7*100 -> 6000 | AZ7: =AV7*100 -> 0 | BA7: =AW7*300 -> 0 | BB7: =AX7*300 -> 3600 | BC7: 61 | BD7: 0 | BE7: 0 | BF7: 16 | BG7: =BC7*100 -> 6100 | BH7: =BD7*100 -> 0 | BI7: =BE7*300 -> 0 | BJ7: =BF7*300 -> 4800 | BK7: 61 | BL7: 0 | BM7: 0 | BN7: 16 | BO7: =BK7*100 -> 6100 | BP7: =BL7*100 -> 0 | BQ7: =BM7*300 -> 0 | BR7: =BN7*300 -> 4800 | BS7: 58 | BT7: 0 | BU7: 0 | BV7: 18 | BW7: =BS7*100 -> 5800 | BX7: =BT7*100 -> 0 | BY7: =BU7*300 -> 0 | BZ7: =BV7*300 -> 5400
A8: 5 | B8: Angelique BYUKUSENGE | G8: 38 | H8: 0 | I8: 0 | J8: 16 | K8: =G8*100 -> 3800 | L8: =H8*100 -> 0 | M8: =I8*300 -> 0 | N8: =J8*300 -> 4800 | O8: 37 | P8: 0 | Q8: 0 | R8: 16 | S8: =O8*100 -> 3700 | T8: =P8*100 -> 0 | U8: =Q8*300 -> 0 | V8: =R8*300 -> 4800 | W8: 40 | X8: 0 | Y8: 0 | Z8: 20 | AA8: =W8*100 -> 4000 | AB8: =X8*100 -> 0 | AC8: =Y8*300 -> 0 | AD8: =Z8*300 -> 6000 | AE8: 41 | AF8: 0 | AG8: 0 | AH8: 20 | AI8: =AE8*100 -> 4100 | AJ8: =AF8*100 -> 0 | AK8: =AG8*300 -> 0 | AL8: =AH8*300 -> 6000 | AM8: 44 | AN8: 0 | AO8: 0 | AP8: 20 | AQ8: =AM8*100 -> 4400 | AR8: =AN8*100 -> 0 | AS8: =AO8*300 -> 0 | AT8: =AP8*300 -> 6000 | AU8: 43 | AV8: 0 | AW8: 0 | AX8: 20 | AY8: =AU8*100 -> 4300 | AZ8: =AV8*100 -> 0 | BA8: =AW8*300 -> 0 | BB8: =AX8*300 -> 6000 | BC8: 42 | BD8: 0 | BE8: 0 | BF8: 20 | BG8: =BC8*100 -> 4200 | BH8: =BD8*100 -> 0 | BI8: =BE8*300 -> 0 | BJ8: =BF8*300 -> 6000 | BK8: 42 | BL8: 0 | BM8: 0 | BN8: 20 | BO8: =BK8*100 -> 4200 | BP8: =BL8*100 -> 0 | BQ8: =BM8*300 -> 0 | BR8: =BN8*300 -> 6000 | BS8: 50 | BT8: 0 | BU8: 0 | BV8: 20 | BW8: =BS8*100 -> 5000 | BX8: =BT8*100 -> 0 | BY8: =BU8*300 -> 0 | BZ8: =BV8*300 -> 6000
A9: 6 | B9: Angelique MUHAWENIMANA | G9: 30 | H9: 0 | I9: 0 | J9: 20 | K9: =G9*100 -> 3000 | L9: =H9*100 -> 0 | M9: =I9*300 -> 0 | N9: =J9*300 -> 6000 | O9: 35 | P9: 0 | Q9: 0 | R9: 20 | S9: =O9*100 -> 3500 | T9: =P9*100 -> 0 | U9: =Q9*300 -> 0 | V9: =R9*300 -> 6000 | W9: 32 | X9: 0 | Y9: 0 | Z9: 16 | AA9: =W9*100 -> 3200 | AB9: =X9*100 -> 0 | AC9: =Y9*300 -> 0 | AD9: =Z9*300 -> 4800 | AE9: 33 | AF9: 0 | AG9: 0 | AH9: 18 | AI9: =AE9*100 -> 3300 | AJ9: =AF9*100 -> 0 | AK9: =AG9*300 -> 0 | AL9: =AH9*300 -> 5400 | AM9: 34 | AN9: 0 | AO9: 0 | AP9: 15 | AQ9: =AM9*100 -> 3400 | AR9: =AN9*100 -> 0 | AS9: =AO9*300 -> 0 | AT9: =AP9*300 -> 4500 | AU9: 36 | AV9: 0 | AW9: 0 | AX9: 15 | AY9: =AU9*100 -> 3600 | AZ9: =AV9*100 -> 0 | BA9: =AW9*300 -> 0 | BB9: =AX9*300 -> 4500 | BC9: 38 | BD9: 0 | BE9: 0 | BF9: 19 | BG9: =BC9*100 -> 3800 | BH9: =BD9*100 -> 0 | BI9: =BE9*300 -> 0 | BJ9: =BF9*300 -> 5700 | BK9: 40 | BL9: 0 | BM9: 0 | BN9: 19 | BO9: =BK9*100 -> 4000 | BP9: =BL9*100 -> 0 | BQ9: =BM9*300 -> 0 | BR9: =BN9*300 -> 5700 | BS9: 44 | BT9: 0 | BU9: 0 | BV9: 19 | BW9: =BS9*100 -> 4400 | BX9: =BT9*100 -> 0 | BY9: =BU9*300 -> 0 | BZ9: =BV9*300 -> 5700
A10: 7 | B10: Angelique MUKANDORI | G10: 50 | H10: 0 | I10: 0 | J10: 20 | K10: =G10*100 -> 5000 | L10: =H10*100 -> 0 | M10: =I10*300 -> 0 | N10: =J10*300 -> 6000 | O10: 45 | P10: 0 | Q10: 0 | R10: 18 | S10: =O10*100 -> 4500 | T10: =P10*100 -> 0 | U10: =Q10*300 -> 0 | V10: =R10*300 -> 5400 | W10: 50 | X10: 0 | Y10: 0 | Z10: 20 | AA10: =W10*100 -> 5000 | AB10: =X10*100 -> 0 | AC10: =Y10*300 -> 0 | AD10: =Z10*300 -> 6000 | AE10: 48 | AF10: 0 | AG10: 0 | AH10: 20 | AI10: =AE10*100 -> 4800 | AJ10: =AF10*100 -> 0 | AK10: =AG10*300 -> 0 | AL10: =AH10*300 -> 6000 | AM10: 52 | AN10: 0 | AO10: 0 | AP10: 20 | AQ10: =AM10*100 -> 5200 | AR10: =AN10*100 -> 0 | AS10: =AO10*300 -> 0 | AT10: =AP10*300 -> 6000 | AU10: 51 | AV10: 0 | AW10: 0 | AX10: 16 | AY10: =AU10*100 -> 5100 | AZ10: =AV10*100 -> 0 | BA10: =AW10*300 -> 0 | BB10: =AX10*300 -> 4800 | BC10: 50 | BD10: 0 | BE10: 0 | BF10: 16 | BG10: =BC10*100 -> 5000 | BH10: =BD10*100 -> 0 | BI10: =BE10*300 -> 0 | BJ10: =BF10*300 -> 4800 | BK10: 52 | BL10: 0 | BM10: 0 | BN10: 16 | BO10: =BK10*100 -> 5200 | BP10: =BL10*100 -> 0 | BQ10: =BM10*300 -> 0 | BR10: =BN10*300 -> 4800 | BS10: 52 | BT10: 0 | BU10: 0 | BV10: 16 | BW10: =BS10*100 -> 5200 | BX10: =BT10*100 -> 0 | BY10: =BU10*300 -> 0 | BZ10: =BV10*300 -> 4800
A11: 8 | B11: Angelique NYIRANEZA | G11: 50 | H11: 0 | I11: 0 | J11: 20 | K11: =G11*100 -> 5000 | L11: =H11*100 -> 0 | M11: =I11*300 -> 0 | N11: =J11*300 -> 6000 | O11: 42 | P11: 0 | Q11: 0 | R11: 20 | S11: =O11*100 -> 4200 | T11: =P11*100 -> 0 | U11: =Q11*300 -> 0 | V11: =R11*300 -> 6000 | W11: 44 | X11: 0 | Y11: 0 | Z11: 20 | AA11: =W11*100 -> 4400 | AB11: =X11*100 -> 0 | AC11: =Y11*300 -> 0 | AD11: =Z11*300 -> 6000 | AE11: 52 | AF11: 0 | AG11: 0 | AH11: 18 | AI11: =AE11*100 -> 5200 | AJ11: =AF11*100 -> 0 | AK11: =AG11*300 -> 0 | AL11: =AH11*300 -> 5400 | AM11: 50 | AN11: 0 | AO11: 0 | AP11: 15 | AQ11: =AM11*100 -> 5000 | AR11: =AN11*100 -> 0 | AS11: =AO11*300 -> 0 | AT11: =AP11*300 -> 4500 | AU11: 50 | AV11: 0 | AW11: 0 | AX11: 14 | AY11: =AU11*100 -> 5000 | AZ11: =AV11*100 -> 0 | BA11: =AW11*300 -> 0 | BB11: =AX11*300 -> 4200 | BC11: 54 | BD11: 0 | BE11: 0 | BF11: 18 | BG11: =BC11*100 -> 5400 | BH11: =BD11*100 -> 0 | BI11: =BE11*300 -> 0 | BJ11: =BF11*300 -> 5400 | BK11: 54 | BL11: 0 | BM11: 0 | BN11: 18 | BO11: =BK11*100 -> 5400 | BP11: =BL11*100 -> 0 | BQ11: =BM11*300 -> 0 | BR11: =BN11*300 -> 5400 | BS11: 54 | BT11: 0 | BU11: 0 | BV11: 18 | BW11: =BS11*100 -> 5400 | BX11: =BT11*100 -> 0 | BY11: =BU11*300 -> 0 | BZ11: =BV11*300 -> 5400
A12: 9 | B12: Anitha GATESI | G12: 42 | H12: 0 | I12: 0 | J12: 5 | K12: =G12*100 -> 4200 | L12: =H12*100 -> 0 | M12: =I12*300 -> 0 | N12: =J12*300 -> 1500 | O12: 55 | P12: 0 | Q12: 0 | R12: 10 | S12: =O12*100 -> 5500 | T12: =P12*100 -> 0 | U12: =Q12*300 -> 0 | V12: =R12*300 -> 3000 | W12: 52 | X12: 0 | Y12: 0 | Z12: 12 | AA12: =W12*100 -> 5200 | AB12: =X12*100 -> 0 | AC12: =Y12*300 -> 0 | AD12: =Z12*300 -> 3600 | AE12: 46 | AF12: 0 | AG12: 0 | AH12: 16 | AI12: =AE12*100 -> 4600 | AJ12: =AF12*100 -> 0 | AK12: =AG12*300 -> 0 | AL12: =AH12*300 -> 4800 | AM12: 44 | AN12: 0 | AO12: 0 | AP12: 12 | AQ12: =AM12*100 -> 4400 | AR12: =AN12*100 -> 0 | AS12: =AO12*300 -> 0 | AT12: =AP12*300 -> 3600 | AU12: 46 | AV12: 0 | AW12: 0 | AX12: 18 | AY12: =AU12*100 -> 4600 | AZ12: =AV12*100 -> 0 | BA12: =AW12*300 -> 0 | BB12: =AX12*300 -> 5400 | BC12: 48 | BD12: 0 | BE12: 0 | BF12: 20 | BG12: =BC12*100 -> 4800 | BH12: =BD12*100 -> 0 | BI12: =BE12*300 -> 0 | BJ12: =BF12*300 -> 6000 | BK12: 48 | BL12: 0 | BM12: 0 | BN12: 20 | BO12: =BK12*100 -> 4800 | BP12: =BL12*100 -> 0 | BQ12: =BM12*300 -> 0 | BR12: =BN12*300 -> 6000 | BS12: 48 | BT12: 0 | BU12: 0 | BV12: 20 | BW12: =BS12*100 -> 4800 | BX12: =BT12*100 -> 0 | BY12: =BU12*300 -> 0 | BZ12: =BV12*300 -> 6000
A13: 10 | B13: Athanasie MUKAGASHUGI | G13: 32 | H13: 0 | I13: 0 | J13: 15 | K13: =G13*100 -> 3200 | L13: =H13*100 -> 0 | M13: =I13*300 -> 0 | N13: =J13*300 -> 4500 | O13: 50 | P13: 0 | Q13: 0 | R13: 15 | S13: =O13*100 -> 5000 | T13: =P13*100 -> 0 | U13: =Q13*300 -> 0 | V13: =R13*300 -> 4500 | W13: 53 | X13: 0 | Y13: 0 | Z13: 16 | AA13: =W13*100 -> 5300 | AB13: =X13*100 -> 0 | AC13: =Y13*300 -> 0 | AD13: =Z13*300 -> 4800 | AE13: 56 | AF13: 0 | AG13: 0 | AH13: 15 | AI13: =AE13*100 -> 5600 | AJ13: =AF13*100 -> 0 | AK13: =AG13*300 -> 0 | AL13: =AH13*300 -> 4500 | AM13: 32 | AN13: 0 | AO13: 0 | AP13: 20 | AQ13: =AM13*100 -> 3200 | AR13: =AN13*100 -> 0 | AS13: =AO13*300 -> 0 | AT13: =AP13*300 -> 6000 | AU13: 32 | AV13: 0 | AW13: 0 | AX13: 20 | AY13: =AU13*100 -> 3200 | AZ13: =AV13*100 -> 0 | BA13: =AW13*300 -> 0 | BB13: =AX13*300 -> 6000 | BC13: 33 | BD13: 0 | BE13: 0 | BF13: 20 | BG13: =BC13*100 -> 3300 | BH13: =BD13*100 -> 0 | BI13: =BE13*300 -> 0 | BJ13: =BF13*300 -> 6000 | BK13: 38 | BL13: 0 | BM13: 0 | BN13: 20 | BO13: =BK13*100 -> 3800 | BP13: =BL13*100 -> 0 | BQ13: =BM13*300 -> 0 | BR13: =BN13*300 -> 6000 | BS13: 38 | BT13: 0 | BU13: 0 | BV13: 20 | BW13: =BS13*100 -> 3800 | BX13: =BT13*100 -> 0 | BY13: =BU13*300 -> 0 | BZ13: =BV13*300 -> 6000
A14: 11 | B14: Augustin NGIRABATWARE | G14: 50 | H14: 0 | I14: 0 | J14: 18 | K14: =G14*100 -> 5000 | L14: =H14*100 -> 0 | M14: =I14*300 -> 0 | N14: =J14*300 -> 5400 | O14: 38 | P14: 0 | Q14: 0 | R14: 18 | S14: =O14*100 -> 3800 | T14: =P14*100 -> 0 | U14: =Q14*300 -> 0 | V14: =R14*300 -> 5400 | W14: 34 | X14: 0 | Y14: 0 | Z14: 20 | AA14: =W14*100 -> 3400 | AB14: =X14*100 -> 0 | AC14: =Y14*300 -> 0 | AD14: =Z14*300 -> 6000 | AE14: 43 | AF14: 0 | AG14: 0 | AH14: 16 | AI14: =AE14*100 -> 4300 | AJ14: =AF14*100 -> 0 | AK14: =AG14*300 -> 0 | AL14: =AH14*300 -> 4800 | AM14: 50 | AN14: 0 | AO14: 0 | AP14: 20 | AQ14: =AM14*100 -> 5000 | AR14: =AN14*100 -> 0 | AS14: =AO14*300 -> 0 | AT14: =AP14*300 -> 6000 | AU14: 50 | AV14: 0 | AW14: 0 | AX14: 20 | AY14: =AU14*100 -> 5000 | AZ14: =AV14*100 -> 0 | BA14: =AW14*300 -> 0 | BB14: =AX14*300 -> 6000 | BC14: 50 | BD14: 0 | BE14: 0 | BF14: 18 | BG14: =BC14*100 -> 5000 | BH14: =BD14*100 -> 0 | BI14: =BE14*300 -> 0 | BJ14: =BF14*300 -> 5400 | BK14: 53 | BL14: 0 | BM14: 0 | BN14: 20 | BO14: =BK14*100 -> 5300 | BP14: =BL14*100 -> 0 | BQ14: =BM14*300 -> 0 | BR14: =BN14*300 -> 6000 | BS14: 53 | BT14: 0 | BU14: 0 | BV14: 20 | BW14: =BS14*100 -> 5300 | BX14: =BT14*100 -> 0 | BY14: =BU14*300 -> 0 | BZ14: =BV14*300 -> 6000
A15: 12 | B15: Beatrice MUHORAKEYE | G15: 10 | H15: 0 | I15: 0 | J15: 14 | K15: =G15*100 -> 1000 | L15: =H15*100 -> 0 | M15: =I15*300 -> 0 | N15: =J15*300 -> 4200 | O15: 25 | P15: 0 | Q15: 0 | R15: 15 | S15: =O15*100 -> 2500 | T15: =P15*100 -> 0 | U15: =Q15*300 -> 0 | V15: =R15*300 -> 4500 | W15: 28 | X15: 0 | Y15: 0 | Z15: 12 | AA15: =W15*100 -> 2800 | AB15: =X15*100 -> 0 | AC15: =Y15*300 -> 0 | AD15: =Z15*300 -> 3600 | AE15: 30 | AF15: 0 | AG15: 0 | AH15: 14 | AI15: =AE15*100 -> 3000 | AJ15: =AF15*100 -> 0 | AK15: =AG15*300 -> 0 | AL15: =AH15*300 -> 4200 | AM15: 31 | AN15: 0 | AO15: 0 | AP15: 10 | AQ15: =AM15*100 -> 3100 | AR15: =AN15*100 -> 0 | AS15: =AO15*300 -> 0 | AT15: =AP15*300 -> 3000 | AU15: 43 | AV15: 0 | AW15: 0 | AX15: 12 | AY15: =AU15*100 -> 4300 | AZ15: =AV15*100 -> 0 | BA15: =AW15*300 -> 0 | BB15: =AX15*300 -> 3600 | BC15: 45 | BD15: 0 | BE15: 0 | BF15: 12 | BG15: =BC15*100 -> 4500 | BH15: =BD15*100 -> 0 | BI15: =BE15*300 -> 0 | BJ15: =BF15*300 -> 3600 | BK15: 48 | BL15: 0 | BM15: 0 | BN15: 20 | BO15: =BK15*100 -> 4800 | BP15: =BL15*100 -> 0 | BQ15: =BM15*300 -> 0 | BR15: =BN15*300 -> 6000 | BS15: 53 | BT15: 0 | BU15: 0 | BV15: 20 | BW15: =BS15*100 -> 5300 | BX15: =BT15*100 -> 0 | BY15: =BU15*300 -> 0 | BZ15: =BV15*300 -> 6000
... A84: 81 | B84: Seraphine MUKAMANA | G84: 36 | H84: 0 | I84: 0 | J84: 0 | K84: =G84*100 -> 3600 | L84: =H84*100 -> 0 | M84: =I84*300 -> 0 | N84: =J84*300 -> 0 | O84: 34 | P84: 0 | Q84: 0 | R84: 0 | S84: =O84*100 -> 3400 | T84: =P84*100 -> 0 | U84: =Q84*300 -> 0 | V84: =R84*300 -> 0 | W84: 32 | X84: 0 | Y84: 0 | Z84: 0 | AA84: =W84*100 -> 3200 | AB84: =X84*100 -> 0 | AC84: =Y84*300 -> 0 | AD84: =Z84*300 -> 0 | AE84: 45 | AF84: 0 | AG84: 0 | AH84: 0 | AI84: =AE84*100 -> 4500 | AJ84: =AF84*100 -> 0 | AK84: =AG84*300 -> 0 | AL84: =AH84*300 -> 0 | AM84: 55 | AN84: 0 | AO84: 0 | AP84: 16 | AQ84: =AM84*100 -> 5500 | AR84: =AN84*100 -> 0 | AS84: =AO84*300 -> 0 | AT84: =AP84*300 -> 4800 | AU84: 50 | AV84: 0 | AW84: 0 | AX84: 10 | AY84: =AU84*100 -> 5000 | AZ84: =AV84*100 -> 0 | BA84: =AW84*300 -> 0 | BB84: =AX84*300 -> 3000 | BC84: 50 | BD84: 0 | BE84: 0 | BF84: 10 | BG84: =BC84*100 -> 5000 | BH84: =BD84*100 -> 0 | BI84: =BE84*300 -> 0 | BJ84: =BF84*300 -> 3000 | BK84: 50 | BL84: 0 | BM84: 0 | BN84: 12 | BO84: =BK84*100 -> 5000 | BP84: =BL84*100 -> 0 | BQ84: =BM84*300 -> 0 | BR84: =BN84*300 -> 3600 | BS84: 50 | BT84: 0 | BU84: 0 | BV84: 12 | BW84: =BS84*100 -> 5000 | BX84: =BT84*100 -> 0 | BY84: =BU84*300 -> 0 | BZ84: =BV84*300 -> 3600
A85: 82 | B85: Shemsa UWAMURERA | G85: 38 | H85: 0 | I85: 0 | J85: 10 | K85: =G85*100 -> 3800 | L85: =H85*100 -> 0 | M85: =I85*300 -> 0 | N85: =J85*300 -> 3000 | O85: 40 | P85: 0 | Q85: 0 | R85: 8 | S85: =O85*100 -> 4000 | T85: =P85*100 -> 0 | U85: =Q85*300 -> 0 | V85: =R85*300 -> 2400 | W85: 43 | X85: 0 | Y85: 0 | Z85: 18 | AA85: =W85*100 -> 4300 | AB85: 0 | AC85: =Y85*300 -> 0 | AD85: =Z85*300 -> 5400 | AE85: 43 | AF85: 0 | AG85: 0 | AH85: 16 | AI85: =AE85*100 -> 4300 | AJ85: 0 | AK85: =AG85*300 -> 0 | AL85: =AH85*300 -> 4800 | AM85: 50 | AN85: 0 | AO85: 0 | AP85: 12 | AQ85: =AM85*100 -> 5000 | AR85: =AN85*100 -> 0 | AS85: =AO85*300 -> 0 | AT85: =AP85*300 -> 3600 | AU85: 52 | AV85: 0 | AW85: 0 | AX85: 13 | AY85: =AU85*100 -> 5200 | AZ85: =AV85*100 -> 0 | BA85: =AW85*300 -> 0 | BB85: =AX85*300 -> 3900 | BC85: 52 | BD85: 0 | BE85: 0 | BF85: 13 | BG85: =BC85*100 -> 5200 | BH85: =BD85*100 -> 0 | BI85: =BE85*300 -> 0 | BJ85: =BF85*300 -> 3900 | BK85: 52 | BL85: 0 | BM85: 0 | BN85: 13 | BO85: =BK85*100 -> 5200 | BP85: =BL85*100 -> 0 | BQ85: =BM85*300 -> 0 | BR85: =BN85*300 -> 3900 | BS85: 52 | BT85: 0 | BU85: 0 | BV85: 13 | BW85: =BS85*100 -> 5200 | BX85: =BT85*100 -> 0 | BY85: =BU85*300 -> 0 | BZ85: =BV85*300 -> 3900
A86: 83 | B86: Slyvine MUSABYIMANA | G86: 30 | H86: 0 | I86: 0 | J86: 8 | K86: =G86*100 -> 3000 | L86: =H86*100 -> 0 | M86: =I86*300 -> 0 | N86: =J86*300 -> 2400 | O86: 32 | P86: 0 | Q86: 0 | R86: 10 | S86: =O86*100 -> 3200 | T86: =P86*100 -> 0 | U86: =Q86*300 -> 0 | V86: =R86*300 -> 3000 | W86: 36 | X86: 0 | Y86: 0 | Z86: 6 | AA86: =W86*100 -> 3600 | AB86: =X86*100 -> 0 | AC86: =Y86*300 -> 0 | AD86: =Z86*300 -> 1800 | AE86: 40 | AF86: 0 | AG86: 0 | AH86: 0 | AI86: =AE86*100 -> 4000 | AJ86: =AF86*100 -> 0 | AK86: =AG86*300 -> 0 | AL86: =AH86*300 -> 0 | AM86: 45 | AN86: 0 | AO86: 0 | AP86: 14 | AQ86: =AM86*100 -> 4500 | AR86: =AN86*100 -> 0 | AS86: =AO86*300 -> 0 | AT86: =AP86*300 -> 4200 | AU86: 45 | AV86: 0 | AW86: 0 | AX86: 20 | AY86: =AU86*100 -> 4500 | AZ86: =AV86*100 -> 0 | BA86: =AW86*300 -> 0 | BB86: =AX86*300 -> 6000 | BC86: 45 | BD86: 0 | BE86: 0 | BF86: 20 | BG86: =BC86*100 -> 4500 | BH86: =BD86*100 -> 0 | BI86: =BE86*300 -> 0 | BJ86: =BF86*300 -> 6000 | BK86: 45 | BL86: 0 | BM86: 0 | BN86: 20 | BO86: =BK86*100 -> 4500 | BP86: =BL86*100 -> 0 | BQ86: =BM86*300 -> 0 | BR86: =BN86*300 -> 6000 | BS86: 45 | BT86: 0 | BU86: 0 | BV86: 20 | BW86: =BS86*100 -> 4500 | BX86: =BT86*100 -> 0 | BY86: =BU86*300 -> 0 | BZ86: =BV86*300 -> 6000
A87: 84 | B87: Solange KAYIRAME | G87: 30 | H87: 0 | I87: 0 | J87: 5 | K87: =G87*100 -> 3000 | L87: =H87*100 -> 0 | M87: =I87*300 -> 0 | N87: =J87*300 -> 1500 | O87: 30 | P87: 0 | Q87: 0 | R87: 11 | S87: =O87*100 -> 3000 | T87: =P87*100 -> 0 | U87: =Q87*300 -> 0 | V87: =R87*300 -> 3300 | W87: 32 | X87: 0 | Y87: 0 | Z87: 11 | AA87: =W87*100 -> 3200 | AB87: =X87*100 -> 0 | AC87: =Y87*300 -> 0 | AD87: =Z87*300 -> 3300 | AE87: 44 | AF87: 0 | AG87: 0 | AH87: 12 | AI87: =AE87*100 -> 4400 | AJ87: =AF87*100 -> 0 | AK87: =AG87*300 -> 0 | AL87: =AH87*300 -> 3600 | AM87: 50 | AN87: 0 | AO87: 0 | AP87: 16 | AQ87: =AM87*100 -> 5000 | AR87: =AN87*100 -> 0 | AS87: =AO87*300 -> 0 | AT87: =AP87*300 -> 4800 | AU87: 48 | AV87: 0 | AW87: 0 | AX87: 16 | AY87: =AU87*100 -> 4800 | AZ87: =AV87*100 -> 0 | BA87: =AW87*300 -> 0 | BB87: =AX87*300 -> 4800 | BC87: 48 | BD87: 0 | BE87: 0 | BF87: 16 | BG87: =BC87*100 -> 4800 | BH87: =BD87*100 -> 0 | BI87: =BE87*300 -> 0 | BJ87: =BF87*300 -> 4800 | BK87: 48 | BL87: 0 | BM87: 0 | BN87: 16 | BO87: =BK87*100 -> 4800 | BP87: =BL87*100 -> 0 | BQ87: =BM87*300 -> 0 | BR87: =BN87*300 -> 4800 | BS87: 52 | BT87: 0 | BU87: 0 | BV87: 16 | BW87: =BS87*100 -> 5200 | BX87: =BT87*100 -> 0 | BY87: =BU87*300 -> 0 | BZ87: =BV87*300 -> 4800
A88: 85 | B88: Stephanie MUKAKAKARISA | G88: 29 | H88: 0 | I88: 0 | J88: 10 | K88: =G88*100 -> 2900 | L88: =H88*100 -> 0 | M88: =I88*300 -> 0 | N88: =J88*300 -> 3000 | O88: 32 | P88: 0 | Q88: 0 | R88: 12 | S88: =O88*100 -> 3200 | T88: =P88*100 -> 0 | U88: =Q88*300 -> 0 | V88: =R88*300 -> 3600 | W88: 34 | X88: 0 | Y88: 0 | Z88: 12 | AA88: =W88*100 -> 3400 | AB88: =X88*100 -> 0 | AC88: =Y88*300 -> 0 | AD88: =Z88*300 -> 3600 | AE88: 34 | AF88: 0 | AG88: 0 | AH88: 16 | AI88: =AE88*100 -> 3400 | AJ88: =AF88*100 -> 0 | AK88: =AG88*300 -> 0 | AL88: =AH88*300 -> 4800 | AM88: 45 | AN88: 0 | AO88: 0 | AP88: 20 | AQ88: =AM88*100 -> 4500 | AR88: =AN88*100 -> 0 | AS88: =AO88*300 -> 0 | AT88: =AP88*300 -> 6000 | AU88: 45 | AV88: 0 | AW88: 0 | AX88: 17 | AY88: =AU88*100 -> 4500 | AZ88: =AV88*100 -> 0 | BA88: =AW88*300 -> 0 | BB88: =AX88*300 -> 5100 | BC88: 45 | BD88: 0 | BE88: 0 | BF88: 17 | BG88: =BC88*100 -> 4500 | BH88: =BD88*100 -> 0 | BI88: =BE88*300 -> 0 | BJ88: =BF88*300 -> 5100 | BK88: 52 | BL88: 0 | BM88: 0 | BN88: 11 | BO88: =BK88*100 -> 5200 | BP88: =BL88*100 -> 0 | BQ88: =BM88*300 -> 0 | BR88: =BN88*300 -> 3300 | BS88: 52 | BT88: 0 | BU88: 0 | BV88: 11 | BW88: =BS88*100 -> 5200 | BX88: =BT88*100 -> 0 | BY88: =BU88*300 -> 0 | BZ88: =BV88*300 -> 3300
A89: 86 | B89: Sylidio MUNYEMANA | G89: 0 | H89: 30 | I89: 0 | J89: 6 | K89: =G89*100 -> 0 | L89: =H89*100 -> 3000 | M89: =I89*300 -> 0 | N89: =J89*300 -> 1800 | O89: 30 | P89: 30 | Q89: 0 | R89: 12 | S89: =O89*100 -> 3000 | T89: =P89*100 -> 3000 | U89: =Q89*300 -> 0 | V89: =R89*300 -> 3600 | W89: 38 | X89: 30 | Y89: 0 | Z89: 12 | AA89: =W89*100 -> 3800 | AB89: =X89*100 -> 3000 | AC89: =Y89*300 -> 0 | AD89: =Z89*300 -> 3600 | AE89: 38 | AF89: 30 | AG89: 0 | AH89: 12 | AI89: =AE89*100 -> 3800 | AJ89: =AF89*100 -> 3000 | AK89: =AG89*300 -> 0 | AL89: =AH89*300 -> 3600 | AM89: 0 | AN89: 32 | AO89: 0 | AP89: 16 | AQ89: =AM89*100 -> 0 | AR89: =AN89*100 -> 3200 | AS89: =AO89*300 -> 0 | AT89: =AP89*300 -> 4800 | AU89: 0 | AV89: 36 | AW89: 0 | AX89: 20 | AY89: =AU89*100 -> 0 | AZ89: =AV89*100 -> 3600 | BA89: =AW89*300 -> 0 | BB89: =AX89*300 -> 6000 | BC89: 0 | BD89: 38 | BE89: 0 | BF89: 20 | BG89: =BC89*100 -> 0 | BH89: =BD89*100 -> 3800 | BI89: =BE89*300 -> 0 | BJ89: =BF89*300 -> 6000 | BK89: 0 | BL89: 48 | BM89: 0 | BN89: 20 | BO89: =BK89*100 -> 0 | BP89: =BL89*100 -> 4800 | BQ89: =BM89*300 -> 0 | BR89: =BN89*300 -> 6000 | BS89: 0 | BT89: 50 | BU89: 0 | BV89: 20 | BW89: =BS89*100 -> 0 | BX89: =BT89*100 -> 5000 | BY89: =BU89*300 -> 0 | BZ89: =BV89*300 -> 6000
A90: 87 | B90: Sylivie MUTESI | G90: 30 | H90: 0 | I90: 0 | J90: 8 | K90: =G90*100 -> 3000 | L90: =H90*100 -> 0 | M90: =I90*300 -> 0 | N90: =J90*300 -> 2400 | O90: 35 | P90: 0 | Q90: 0 | R90: 4 | S90: =O90*100 -> 3500 | T90: =P90*100 -> 0 | U90: =Q90*300 -> 0 | V90: =R90*300 -> 1200 | W90: 35 | X90: 0 | Y90: 0 | Z90: 8 | AA90: =W90*100 -> 3500 | AB90: =X90*100 -> 0 | AC90: =Y90*300 -> 0 | AD90: =Z90*300 -> 2400 | AE90: 35 | AF90: 0 | AG90: 0 | AH90: 8 | AI90: =AE90*100 -> 3500 | AJ90: =AF90*100 -> 0 | AK90: =AG90*300 -> 0 | AL90: =AH90*300 -> 2400 | AM90: 44 | AN90: 0 | AO90: 0 | AP90: 20 | AQ90: =AM90*100 -> 4400 | AR90: =AN90*100 -> 0 | AS90: =AO90*300 -> 0 | AT90: =AP90*300 -> 6000 | AU90: 46 | AV90: 0 | AW90: 0 | AX90: 18 | AY90: =AU90*100 -> 4600 | AZ90: =AV90*100 -> 0 | BA90: =AW90*300 -> 0 | BB90: =AX90*300 -> 5400 | BC90: 46 | BD90: 0 | BE90: 0 | BF90: 18 | BG90: =BC90*100 -> 4600 | BH90: =BD90*100 -> 0 | BI90: =BE90*300 -> 0 | BJ90: =BF90*300 -> 5400 | BK90: 48 | BL90: 0 | BM90: 0 | BN90: 18 | BO90: =BK90*100 -> 4800 | BP90: =BL90*100 -> 0 | BQ90: =BM90*300 -> 0 | BR90: =BN90*300 -> 5400 | BS90: 48 | BT90: 0 | BU90: 0 | BV90: 18 | BW90: =BS90*100 -> 4800 | BX90: =BT90*100 -> 0 | BY90: =BU90*300 -> 0 | BZ90: =BV90*300 -> 5400
A91: 88 | B91: Theogene BAHIGI | G91: 35 | H91: 0 | I91: 0 | J91: 15 | K91: =G91*100 -> 3500 | L91: =H91*100 -> 0 | M91: =I91*300 -> 0 | N91: =J91*300 -> 4500 | O91: 30 | P91: 0 | Q91: 0 | R91: 12 | S91: =O91*100 -> 3000 | T91: =P91*100 -> 0 | U91: =Q91*300 -> 0 | V91: =R91*300 -> 3600 | W91: 28 | X91: 0 | Y91: 0 | Z91: 12 | AA91: =W91*100 -> 2800 | AB91: =X91*100 -> 0 | AC91: =Y91*300 -> 0 | AD91: =Z91*300 -> 3600 | AE91: 30 | AF91: 0 | AG91: 0 | AH91: 20 | AI91: =AE91*100 -> 3000 | AJ91: =AF91*100 -> 0 | AK91: =AG91*300 -> 0 | AL91: =AH91*300 -> 6000 | AM91: 55 | AN91: 0 | AO91: 0 | AP91: 15 | AQ91: =AM91*100 -> 5500 | AR91: =AN91*100 -> 0 | AS91: =AO91*300 -> 0 | AT91: =AP91*300 -> 4500 | AU91: 55 | AV91: 0 | AW91: 0 | AX91: 12 | AY91: =AU91*100 -> 5500 | AZ91: =AV91*100 -> 0 | BA91: =AW91*300 -> 0 | BB91: =AX91*300 -> 3600 | BC91: 55 | BD91: 0 | BE91: 0 | BF91: 8 | BG91: =BC91*100 -> 5500 | BH91: =BD91*100 -> 0 | BI91: =BE91*300 -> 0 | BJ91: =BF91*300 -> 2400 | BK91: 55 | BL91: 0 | BM91: 0 | BN91: 8 | BO91: =BK91*100 -> 5500 | BP91: =BL91*100 -> 0 | BQ91: =BM91*300 -> 0 | BR91: =BN91*300 -> 2400 | BS91: 55 | BT91: 0 | BU91: 0 | BV91: 20 | BW91: =BS91*100 -> 5500 | BX91: =BT91*100 -> 0 | BY91: =BU91*300 -> 0 | BZ91: =BV91*300 -> 6000
A92: 89 | B92: Theogene NSHIMIYIMANA | G92: 37 | H92: 0 | I92: 0 | J92: 18 | K92: =G92*100 -> 3700 | L92: =H92*100 -> 0 | M92: =I92*300 -> 0 | N92: =J92*300 -> 5400 | O92: 32 | P92: 0 | Q92: 0 | R92: 15 | S92: =O92*100 -> 3200 | T92: =P92*100 -> 0 | U92: =Q92*300 -> 0 | V92: =R92*300 -> 4500 | W92: 32 | X92: 0 | Y92: 0 | Z92: 15 | AA92: =W92*100 -> 3200 | AB92: =X92*100 -> 0 | AC92: =Y92*300 -> 0 | AD92: =Z92*300 -> 4500 | AE92: 36 | AF92: 0 | AG92: 0 | AH92: 16 | AI92: =AE92*100 -> 3600 | AJ92: =AF92*100 -> 0 | AK92: =AG92*300 -> 0 | AL92: =AH92*300 -> 4800 | AM92: 48 | AN92: 0 | AO92: 0 | AP92: 18 | AQ92: =AM92*100 -> 4800 | AR92: =AN92*100 -> 0 | AS92: =AO92*300 -> 0 | AT92: =AP92*300 -> 5400 | AU92: 48 | AV92: 0 | AW92: 0 | AX92: 18 | AY92: =AU92*100 -> 4800 | AZ92: =AV92*100 -> 0 | BA92: =AW92*300 -> 0 | BB92: =AX92*300 -> 5400 | BC92: 50 | BD92: 0 | BE92: 0 | BF92: 18 | BG92: =BC92*100 -> 5000 | BH92: =BD92*100 -> 0 | BI92: =BE92*300 -> 0 | BJ92: =BF92*300 -> 5400 | BK92: 51 | BL92: 0 | BM92: 0 | BN92: 18 | BO92: =BK92*100 -> 5100 | BP92: =BL92*100 -> 0 | BQ92: =BM92*300 -> 0 | BR92: =BN92*300 -> 5400 | BS92: 53 | BT92: 0 | BU92: 0 | BV92: 18 | BW92: =BS92*100 -> 5300 | BX92: =BT92*100 -> 0 | BY92: =BU92*300 -> 0 | BZ92: =BV92*300 -> 5400
A93: 90 | B93: Theopista NABAKOBWA | G93: 22 | H93: 0 | I93: 0 | J93: 0 | K93: =G93*100 -> 2200 | L93: =H93*100 -> 0 | M93: =I93*300 -> 0 | N93: =J93*300 -> 0 | O93: 29 | P93: 0 | Q93: 0 | R93: 0 | S93: =O93*100 -> 2900 | T93: =P93*100 -> 0 | U93: =Q93*300 -> 0 | V93: =R93*300 -> 0 | W93: 50 | X93: 0 | Y93: 0 | Z93: 0 | AA93: =W93*100 -> 5000 | AB93: =X93*100 -> 0 | AC93: =Y93*300 -> 0 | AD93: =Z93*300 -> 0 | AE93: 55 | AF93: 0 | AG93: 0 | AH93: 6 | AI93: =AE93*100 -> 5500 | AJ93: =AF93*100 -> 0 | AK93: =AG93*300 -> 0 | AL93: =AH93*300 -> 1800 | AM93: 33 | AN93: 0 | AO93: 0 | AP93: 10 | AQ93: =AM93*100 -> 3300 | AR93: =AN93*100 -> 0 | AS93: =AO93*300 -> 0 | AT93: =AP93*300 -> 3000 | AU93: 36 | AV93: 0 | AW93: 0 | AX93: 12 | AY93: =AU93*100 -> 3600 | AZ93: =AV93*100 -> 0 | BA93: =AW93*300 -> 0 | BB93: =AX93*300 -> 3600 | BC93: 36 | BD93: 0 | BE93: 0 | BF93: 12 | BG93: =BC93*100 -> 3600 | BH93: =BD93*100 -> 0 | BI93: =BE93*300 -> 0 | BJ93: =BF93*300 -> 3600 | BK93: 35 | BL93: 0 | BM93: 0 | BN93: 12 | BO93: =BK93*100 -> 3500 | BP93: =BL93*100 -> 0 | BQ93: =BM93*300 -> 0 | BR93: =BN93*300 -> 3600 | BS93: 38 | BT93: 0 | BU93: 0 | BV93: 12 | BW93: =BS93*100 -> 3800 | BX93: =BT93*100 -> 0 | BY93: =BU93*300 -> 0 | BZ93: =BV93*300 -> 3600
A94: 91 | B94: Valerie MUKAGAKWANDI | G94: 25 | H94: 0 | I94: 0 | J94: 8 | K94: =G94*100 -> 2500 | L94: =H94*100 -> 0 | M94: =I94*300 -> 0 | N94: =J94*300 -> 2400 | O94: 28 | P94: 0 | Q94: 0 | R94: 6 | S94: =O94*100 -> 2800 | T94: =P94*100 -> 0 | U94: =Q94*300 -> 0 | V94: =R94*300 -> 1800 | W94: 32 | X94: 0 | Y94: 0 | Z94: 6 | AA94: =W94*100 -> 3200 | AB94: =X94*100 -> 0 | AC94: =Y94*300 -> 0 | AD94: =Z94*300 -> 1800 | AE94: 36 | AF94: 0 | AG94: 0 | AH94: 8 | AI94: =AE94*100 -> 3600 | AJ94: =AF94*100 -> 0 | AK94: =AG94*300 -> 0 | AL94: =AH94*300 -> 2400 | AM94: 25 | AN94: 0 | AO94: 0 | AP94: 10 | AQ94: =AM94*100 -> 2500 | AR94: =AN94*100 -> 0 | AS94: =AO94*300 -> 0 | AT94: =AP94*300 -> 3000 | AU94: 28 | AV94: 0 | AW94: 0 | AX94: 6 | AY94: =AU94*100 -> 2800 | AZ94: =AV94*100 -> 0 | BA94: =AW94*300 -> 0 | BB94: =AX94*300 -> 1800 | BC94: 60 | BD94: 0 | BE94: 0 | BF94: 6 | BG94: =BC94*100 -> 6000 | BH94: =BD94*100 -> 0 | BI94: =BE94*300 -> 0 | BJ94: =BF94*300 -> 1800 | BK94: 58 | BL94: 0 | BM94: 0 | BN94: 6 | BO94: =BK94*100 -> 5800 | BP94: =BL94*100 -> 0 | BQ94: =BM94*300 -> 0 | BR94: =BN94*300 -> 1800 | BS94: 58 | BT94: 0 | BU94: 0 | BV94: 6 | BW94: =BS94*100 -> 5800 | BX94: =BT94*100 -> 0 | BY94: =BU94*300 -> 0 | BZ94: =BV94*300 -> 1800
A95: 92 | B95: Venantia MUKANYIRIGIRA | G95: 35 | H95: 0 | I95: 0 | J95: 6 | K95: =G95*100 -> 3500 | L95: =H95*100 -> 0 | M95: =I95*300 -> 0 | N95: =J95*300 -> 1800 | O95: 32 | P95: 0 | Q95: 0 | R95: 7 | S95: =O95*100 -> 3200 | T95: =P95*100 -> 0 | U95: =Q95*300 -> 0 | V95: =R95*300 -> 2100 | W95: 30 | X95: 0 | Y95: 0 | Z95: 7 | AA95: =W95*100 -> 3000 | AB95: =X95*100 -> 0 | AC95: =Y95*300 -> 0 | AD95: =Z95*300 -> 2100 | AE95: 32 | AF95: 0 | AG95: 0 | AH95: 7 | AI95: =AE95*100 -> 3200 | AJ95: =AF95*100 -> 0 | AK95: =AG95*300 -> 0 | AL95: =AH95*300 -> 2100 | AM95: 34 | AN95: 0 | AO95: 0 | AP95: 8 | AQ95: =AM95*100 -> 3400 | AR95: =AN95*100 -> 0 | AS95: =AO95*300 -> 0 | AT95: =AP95*300 -> 2400 | AU95: 32 | AV95: 0 | AW95: 0 | AX95: 14 | AY95: =AU95*100 -> 3200 | AZ95: =AV95*100 -> 0 | BA95: =AW95*300 -> 0 | BB95: =AX95*300 -> 4200 | BC95: 32 | BD95: 0 | BE95: 0 | BF95: 12 | BG95: =BC95*100 -> 3200 | BH95: =BD95*100 -> 0 | BI95: =BE95*300 -> 0 | BJ95: =BF95*300 -> 3600 | BK95: 36 | BL95: 0 | BM95: 0 | BN95: 12 | BO95: =BK95*100 -> 3600 | BP95: =BL95*100 -> 0 | BQ95: =BM95*300 -> 0 | BR95: =BN95*300 -> 3600 | BS95: 60 | BT95: 0 | BU95: 0 | BV95: 12 | BW95: =BS95*100 -> 6000 | BX95: =BT95*100 -> 0 | BY95: =BU95*300 -> 0 | BZ95: =BV95*300 -> 3600
A96: 93 | B96: Verena MUKAKAYONDE | G96: 0 | H96: 35 | I96: 0 | J96: 15 | K96: =G96*100 -> 0 | L96: =H96*100 -> 3500 | M96: =I96*300 -> 0 | N96: =J96*300 -> 4500 | O96: 0 | P96: 40 | Q96: 0 | R96: 13 | S96: =O96*100 -> 0 | T96: =P96*100 -> 4000 | U96: =Q96*300 -> 0 | V96: =R96*300 -> 3900 | W96: 0 | X96: 42 | Y96: 0 | Z96: 15 | AA96: =W96*100 -> 0 | AB96: =X96*100 -> 4200 | AC96: =Y96*300 -> 0 | AD96: =Z96*300 -> 4500 | AE96: 0 | AF96: 42 | AG96: 0 | AH96: 16 | AI96: =AE96*100 -> 0 | AJ96: =AF96*100 -> 4200 | AK96: =AG96*300 -> 0 | AL96: =AH96*300 -> 4800 | AM96: 0 | AN96: 40 | AO96: 0 | AP96: 15 | AQ96: =AM96*100 -> 0 | AR96: =AN96*100 -> 4000 | AS96: =AO96*300 -> 0 | AT96: =AP96*300 -> 4500 | AU96: 0 | AV96: 40 | AW96: 0 | AX96: 9 | AY96: =AU96*100 -> 0 | AZ96: =AV96*100 -> 4000 | BA96: =AW96*300 -> 0 | BB96: =AX96*300 -> 2700 | BC96: 0 | BD96: 42 | BE96: 0 | BF96: 9 | BG96: =BC96*100 -> 0 | BH96: =BD96*100 -> 4200 | BI96: =BE96*300 -> 0 | BJ96: =BF96*300 -> 2700 | BK96: 0 | BL96: 40 | BM96: 0 | BN96: 9 | BO96: =BK96*100 -> 0 | BP96: =BL96*100 -> 4000 | BQ96: =BM96*300 -> 0 | BR96: =BN96*300 -> 2700 | BS96: 0 | BT96: 52 | BU96: 0 | BV96: 20 | BW96: =BS96*100 -> 0 | BX96: =BT96*100 -> 5200 | BY96: =BU96*300 -> 0 | BZ96: =BV96*300 -> 6000
A97: 94 | B97: Vestine KAMBARANGWE | G97: 35 | H97: 0 | I97: 0 | J97: 0 | K97: =G97*100 -> 3500 | L97: =H97*100 -> 0 | M97: =I97*300 -> 0 | N97: =J97*300 -> 0 | O97: 30 | P97: 0 | Q97: 0 | R97: 0 | S97: =O97*100 -> 3000 | T97: =P97*100 -> 0 | U97: =Q97*300 -> 0 | V97: =R97*300 -> 0 | W97: 50 | X97: 0 | Y97: 0 | Z97: 0 | AA97: =W97*100 -> 5000 | AB97: =X97*100 -> 0 | AC97: =Y97*300 -> 0 | AD97: =Z97*300 -> 0 | AE97: 50 | AF97: 0 | AG97: 0 | AH97: 0 | AI97: =AE97*100 -> 5000 | AJ97: =AF97*100 -> 0 | AK97: =AG97*300 -> 0 | AL97: =AH97*300 -> 0 | AM97: 50 | AN97: 0 | AO97: 0 | AP97: 0 | AQ97: =AM97*100 -> 5000 | AR97: =AN97*100 -> 0 | AS97: =AO97*300 -> 0 | AT97: =AP97*300 -> 0 | AU97: 58 | AV97: 0 | AW97: 0 | AX97: 0 | AY97: =AU97*100 -> 5800 | AZ97: =AV97*100 -> 0 | BA97: =AW97*300 -> 0 | BB97: =AX97*300 -> 0 | BC97: 58 | BD97: 0 | BE97: 0 | BF97: 2 | BG97: =BC97*100 -> 5800 | BH97: =BD97*100 -> 0 | BI97: =BE97*300 -> 0 | BJ97: =BF97*300 -> 600 | BK97: 58 | BL97: 0 | BM97: 0 | BN97: 2 | BO97: =BK97*100 -> 5800 | BP97: =BL97*100 -> 0 | BQ97: =BM97*300 -> 0 | BR97: =BN97*300 -> 600 | BS97: 58 | BT97: 0 | BU97: 0 | BV97: 2 | BW97: =BS97*100 -> 5800 | BX97: =BT97*100 -> 0 | BY97: =BU97*300 -> 0 | BZ97: =BV97*300 -> 600
... A103: 100 | B103: Yvonne UWIMANA | G103: 32 | H103: 0 | I103: 0 | J103: 0 | K103: =G103*100 -> 3200 | L103: =H103*100 -> 0 | M103: =I103*300 -> 0 | N103: =J103*300 -> 0 | O103: 35 | P103: 0 | Q103: 0 | R103: 0 | S103: =O103*100 -> 3500 | T103: =P103*100 -> 0 | U103: =Q103*300 -> 0 | V103: =R103*300 -> 0 | W103: 34 | X103: 0 | Y103: 0 | Z103: 0 | AA103: =W103*100 -> 3400 | AB103: =X103*100 -> 0 | AC103: =Y103*300 -> 0 | AD103: =Z103*300 -> 0 | AE103: 34 | AF103: 0 | AG103: 0 | AH103: 0 | AI103: =AE103*100 -> 3400 | AJ103: =AF103*100 -> 0 | AK103: =AG103*300 -> 0 | AL103: =AH103*300 -> 0 | AM103: 44 | AN103: 0 | AO103: 0 | AP103: 0 | AQ103: =AM103*100 -> 4400 | AR103: =AN103*100 -> 0 | AS103: =AO103*300 -> 0 | AT103: =AP103*300 -> 0 | AU103: 50 | AV103: 0 | AW103: 0 | AX103: 0 | AY103: =AU103*100 -> 5000 | AZ103: =AV103*100 -> 0 | BA103: =AW103*300 -> 0 | BB103: =AX103*300 -> 0 | BC103: 55 | BD103: 0 | BE103: 0 | BF103: 0 | BG103: =BC103*100 -> 5500 | BH103: =BD103*100 -> 0 | BI103: =BE103*300 -> 0 | BJ103: =BF103*300 -> 0 | BK103: 55 | BL103: 0 | BM103: 0 | BN103: 0 | BO103: =BK103*100 -> 5500 | BP103: =BL103*100 -> 0 | BQ103: =BM103*300 -> 0 | BR103: =BN103*300 -> 0 | BS103: 55 | BT103: 0 | BU103: 0 | BV103: 3 | BW103: =BS103*100 -> 5500 | BX103: =BT103*100 -> 0 | BY103: =BU103*300 -> 0 | BZ103: =BV103*300 -> 900
B104: Total | G104: =SUM(G4:G103) -> 3423.5 | H104: =SUM(H4:H103) -> 179 | I104: 0 | J104: =SUM(J4:J103) -> 1234.6 | K104: =G104*100 -> 342350 | L104: =H104*100 -> 17900 | M104: =I104*300 -> 0 | N104: =J104*300 -> 370380 | O104: =SUM(O4:O103) -> 3648 | P104: =SUM(P4:P103) -> 184 | Q104: 0 | R104: =SUM(R4:R103) -> 1297 | S104: =O104*100 -> 364800 | T104: =P104*100 -> 18400 | U104: =Q104*300 -> 0 | V104: =R104*300 -> 389100 | W104: =SUM(W4:W103) -> 3794 | X104: =SUM(X4:X103) -> 196 | Y104: 0 | Z104: =SUM(Z4:Z103) -> 1343 | AA104: =W104*100 -> 379400 | AB104: =X104*100 -> 19600 | AC104: =Y104*300 -> 0 | AD104: =Z104*300 -> 402900 | AE104: =SUM(AE4:AE103) -> 3929 | AF104: =SUM(AF4:AF103) -> 196 | AG104: 0 | AH104: =SUM(AH4:AH103) -> 1430 | AI104: =AE104*100 -> 392900 | AJ104: =AF104*100 -> 19600 | AK104: =AG104*300 -> 0 | AL104: =AH104*300 -> 429000 | AM104: =SUM(AM4:AM103) -> 4104 | AN104: =SUM(AN4:AN103) -> 209 | AO104: 0 | AP104: =SUM(AP4:AP103) -> 1482 | AQ104: =AM104*100 -> 410400 | AR104: =AN104*100 -> 20900 | AS104: =AO104*300 -> 0 | AT104: =AP104*300 -> 444600 | AU104: =SUM(AU4:AU103) -> 4329 | AV104: =SUM(AV4:AV103) -> 226 | AW104: =SUM(AW4:AW103) -> 12 | AX104: =SUM(AX4:AX103) -> 1517 | AY104: =AU104*100 -> 432900 | AZ104: =AV104*100 -> 22600 | BA104: =AW104*300 -> 3600 | BB104: =AX104*300 -> 455100 | BC104: =SUM(BC4:BC103) -> 4503 | BD104: =SUM(BD4:BD103) -> 235 | BE104: =SUM(BE4:BE103) -> 22 | BF104: =SUM(BF4:BF103) -> 1581 | BG104: =BC104*100 -> 450300 | BH104: =BD104*100 -> 23500 | BI104: =BE104*300 -> 6600 | BJ104: =BF104*300 -> 474300 | BK104: =SUM(BK4:BK103) -> 4694 | BL104: =SUM(BL4:BL103) -> 265 | BM104: =SUM(BM4:BM103) -> 29 | BN104: =SUM(BN4:BN103) -> 1641 | BO104: =BK104*100 -> 469400 | BP104: =BL104*100 -> 26500 | BQ104: =BM104*300 -> 8700 | BR104: =BN104*300 -> 492300 | BS104: =SUM(BS4:BS103) -> 4863 | BT104: =SUM(BT4:BT103) -> 294 | BU104: =SUM(BU4:BU103) -> 42 | BV104: =SUM(BV4:BV103) -> 1697 | BW104: =BS104*100 -> 486300 | BX104: =BT104*100 -> 29400 | BY104: =BU104*300 -> 12600 | BZ104: =BV104*300 -> 509100
AR105: =AN105*100 -> 0
G106: 2022 | AU106: 2023
B107: Cookstoves Second Phase Delivery | G107: Aug | O107: September | W107: October | AE107: Nov | AM107: December | AU107: January | BC107: February | BK107: March | BS107: April | CA107: May | CI107: June | CQ107: July | CY107: Auguster | DG107: September | DO107: October | DW107: Novermber | EE107: December
B108: Member | C108: Coop name | D108: Number of people in the household | E108: Monthly household income | F108: Number of meals per person per day | G108: Firewood consumption foraged (kg/month) | H108: Firewood consumption bought(kg/month) | I108: Charcoal consumption (kg/month) | J108: Pellets consumption (Kg/month | K108: Cost of firewood in-kind (RWF/month) | L108: Cost of firewood spent (RWF/month) | M108: Cost of charcoal (RWF/month) | N108: Cost of Pellets (RWF/month) | O108: Firewood consumption foraged (kg/month) | P108: Firewood consumption bought(kg/month) | Q108: Charcoal consumption (kg/month) | R108: Pellets Consumption (Kg/month | S108: Cost of firewood in-kind (RWF/month) | T108: Cost of firewood spent (RWF/month) | U108: Cost of charcoal (RWF/month) | V108: Cost of Pellets (RWF/month) | W108: Firewood consumption foraged (kg/month) | X108: Firewood consumption bought(kg/month) | Y108: Charcoal consumption (kg/month) | Z108: Pellets consumption (Kg/month | AA108: Cost of firewood in-kind (RWF/month) | AB108: Cost of firewood spent (RWF/month) | AC108: Cost of charcoal (RWF/month) | AD108: Cost of Pellets (RWF/month) | AE108: Firewood consumption foraged (kg/month) | AF108: Firewood consumption bought(kg/month) | AG108: Charcoal consumption (kg/month) | AH108: Pellets consumption (Kg/month | AI108: Cost of firewood in-kind (RWF/month) | AJ108: Cost of firewood spent (RWF/month) | AK108: Cost of charcoal (RWF/month) | AL108: Cost of Pellets (RWF/month) | AM108: Firewood consumption foraged (kg/month) | AN108: Firewood consumption bought(kg/month) | AO108: Charcoal consumption (kg/month) | AP108: Pellets consumption (Kg/month | AQ108: Cost of firewood in-kind (RWF/month) | AR108: Cost of firewood spent (RWF/month) | AS108: Cost of charcoal (RWF/month) | AT108: Cost of Pellets (RWF/month) | AU108: Firewood consumption foraged (kg/month) | AV108: Firewood consumption bought(kg/month) | AW108: Charcoal consumption (kg/month) | AX108: Pellets consumption (Kg/month | AY108: Cost of firewood in-kind (RWF/month) | AZ108: Cost of firewood spent (RWF/month) | BA108: Cost of charcoal (RWF/month) | BB108: Cost of Pellets (RWF/month) | BC108: Firewood consumption foraged (kg/month) | BD108: Firewood consumption bought(kg/month) | BE108: Charcoal consumption (kg/month) | BF108: Pellets consumption (Kg/month | BG108: Cost of firewood in-kind (RWF/month) | BH108: Cost of firewood spent (RWF/month) | BI108: Cost of charcoal (RWF/month) | BJ108: Cost of Pellets (RWF/month) | BK108: Firewood consumption foraged (kg/month) | BL108: Firewood consumption bought(kg/month) | BM108: Charcoal consumption (kg/month) | BN108: Pellets consumption (Kg/month | BO108: Cost of firewood in-kind (RWF/month) | BP108: Cost of firewood spent (RWF/month) | BQ108: Cost of charcoal (RWF/month) | BR108: Cost of Pellets (RWF/month) | BS108: Firewood consumption foraged (kg/month) | BT108: Firewood consumption bought(kg/month) | BU108: Charcoal consumption (kg/month) | BV108: Pellets consumption (Kg/month | BW108: Cost of firewood in-kind (RWF/month) | BX108: Cost of firewood spent (RWF/month) | BY108: Cost of charcoal (RWF/month) | BZ108: Cost of Pellets (RWF/month) | CA108: Firewood consumption foraged (kg/month) | CB108: Firewood consumption bought(kg/month) | CC108: Charcoal consumption (kg/month) | CD108: Pellets consumption (Kg/month | CE108: Cost of firewood in-kind (RWF/month) | CF108: Cost of firewood spent (RWF/month) | CG108: Cost of charcoal (RWF/month) | CH108: Cost of Pellets (RWF/month) | CI108: Firewood consumption foraged (kg/month) | CJ108: Firewood consumption bought(kg/month) | CK108: Charcoal consumption (kg/month) | CL108: Pellets consumption (Kg/month | CM108: Cost of firewood in-kind (RWF/month) | CN108: Cost of firewood spent (RWF/month) | CO108: Cost of charcoal (RWF/month) | CP108: Cost of Pellets (RWF/month) | CQ108: Firewood consumption foraged (kg/month) | CR108: Firewood consumption bought(kg/month) | CS108: Charcoal consumption (kg/month) | CT108: Pellets consumption (Kg/month | CU108: Cost of firewood in-kind (RWF/month) | CV108: Cost of firewood spent (RWF/month) | CW108: Cost of charcoal (RWF/month) | CX108: Cost of Pellets (RWF/month) | CY108: Firewood consumption foraged (kg/month) | CZ108: Firewood consumption bought(kg/month) | DA108: Charcoal consumption (kg/month) | DB108: Pellets consumption (Kg/month | DC108: Cost of firewood in-kind (RWF/month) | DD108: Cost of firewood spent (RWF/month) | DE108: Cost of charcoal (RWF/month) | DF108: Cost of Pellets (RWF/month) | DG108: Firewood consumption foraged (kg/month) | DH108: Firewood consumption bought(kg/month) | DI108: Charcoal consumption (kg/month) | DJ108: Pellets consumption (Kg/month | DK108: Cost of firewood in-kind (RWF/month) | DL108: Cost of firewood spent (RWF/month) | DM108: Cost of charcoal (RWF/month) | DN108: Cost of Pellets (RWF/month) | DO108: Firewood consumption foraged (kg/month) | DP108: Firewood consumption bought(kg/month) | DQ108: Charcoal consumption (kg/month) | DR108: Pellets consumption (Kg/month | DS108: Cost of firewood in-kind (RWF/month) | DT108: Cost of firewood spent (RWF/month) | DU108: Cost of charcoal (RWF/month) | DV108: Cost of Pellets (RWF/month) | DW108: Firewood consumption foraged (kg/month) | DX108: Firewood consumption bought(kg/month) | DY108: Charcoal consumption (kg/month) | DZ108: Pellets consumption (Kg/month | EA108: Cost of firewood in-kind (RWF/month) | EB108: Cost of firewood spent (RWF/month) | EC108: Cost of charcoal (RWF/month) | ED108: Cost of Pellets (RWF/month) | EE108: Firewood consumption foraged (kg/month) | EF108: Firewood consumption bought(kg/month) | EG108: Charcoal consumption (kg/month) | EH108: Pellets consumption (Kg/month | EI108: Cost of firewood in-kind (RWF/month) | EJ108: Cost of firewood spent (RWF/month) | EK108: Cost of charcoal (RWF/month) | EL108: Cost of Pellets (RWF/month)
A109: 1 | B109: Adrien Namugire | G109: 56 | H109: 0 | I109: 0 | J109: 20 | K109: =G109*100 -> 5600 | L109: =H109*100 -> 0 | M109: =I109*300 -> 0 | N109: =J109*300 -> 6000 | O109: 54 | P109: 0 | Q109: 0 | R109: 20 | S109: =O109*100 -> 5400 | T109: =P109*100 -> 0 | U109: =Q109*300 -> 0 | V109: =R109*300 -> 6000 | W109: 52 | X109: 0 | Y109: 0 | Z109: 20 | AA109: =W109*100 -> 5200 | AB109: =X109*100 -> 0 | AC109: =Y109*300 -> 0 | AD109: =Z109*300 -> 6000 | AE109: 56 | AF109: 0 | AG109: 0 | AH109: 20 | AI109: =AE109*100 -> 5600 | AJ109: =AF109*100 -> 0 | AK109: =AG109*300 -> 0 | AL109: =AH109*300 -> 6000 | AM109: 54 | AN109: 0 | AO109: 0 | AP109: 20 | AQ109: =AM109*100 -> 5400 | AR109: =AN109*100 -> 0 | AS109: =AO109*300 -> 0 | AT109: =AP109*300 -> 6000 | AU109: 54 | AV109: 0 | AW109: 0 | AX109: 20 | AY109: =AU109*100 -> 5400 | AZ109: =AV109*100 -> 0 | BA109: =AW109*300 -> 0 | BB109: =AX109*300 -> 6000 | BC109: 55 | BD109: 0 | BE109: 0 | BF109: 19 | BG109: =BC109*100 -> 5500 | BH109: =BD109*100 -> 0 | BI109: =BE109*300 -> 0 | BJ109: =BF109*300 -> 5700 | BK109: 56 | BL109: 0 | BM109: 0 | BN109: 18 | BO109: =BK109*100 -> 5600 | BP109: =BL109*100 -> 0 | BQ109: =BM109*300 -> 0 | BR109: =BN109*300 -> 5400 | BS109: 56 | BT109: 0 | BU109: 0 | BV109: 18 | BW109: =BS109*100 -> 5600 | BX109: =BT109*100 -> 0 | BY109: =BU109*300 -> 0 | BZ109: =BV109*300 -> 5400
A110: 2 | B110: Agnes Kankesha | G110: 42 | H110: 0 | I110: 0 | J110: 10 | K110: =G110*100 -> 4200 | L110: =H110*100 -> 0 | M110: =I110*300 -> 0 | N110: =J110*300 -> 3000 | O110: 44 | P110: 0 | Q110: 0 | R110: 20 | S110: =O110*100 -> 4400 | T110: =P110*100 -> 0 | U110: =Q110*300 -> 0 | V110: =R110*300 -> 6000 | W110: 46 | X110: 0 | Y110: 0 | Z110: 15 | AA110: =W110*100 -> 4600 | AB110: =X110*100 -> 0 | AC110: =Y110*300 -> 0 | AD110: =Z110*300 -> 4500 | AE110: 44 | AF110: 0 | AG110: 0 | AH110: 20 | AI110: =AE110*100 -> 4400 | AJ110: =AF110*100 -> 0 | AK110: =AG110*300 -> 0 | AL110: =AH110*300 -> 6000 | AM110: 45 | AN110: 0 | AO110: 0 | AP110: 20 | AQ110: =AM110*100 -> 4500 | AR110: =AN110*100 -> 0 | AS110: =AO110*300 -> 0 | AT110: =AP110*300 -> 6000 | AU110: 44 | AV110: 0 | AW110: 0 | AX110: 20 | AY110: =AU110*100 -> 4400 | AZ110: =AV110*100 -> 0 | BA110: =AW110*300 -> 0 | BB110: =AX110*300 -> 6000 | BC110: 45 | BD110: 0 | BE110: 0 | BF110: 20 | BG110: =BC110*100 -> 4500 | BH110: =BD110*100 -> 0 | BI110: =BE110*300 -> 0 | BJ110: =BF110*300 -> 6000 | BK110: 48 | BL110: 0 | BM110: 0 | BN110: 20 | BO110: =BK110*100 -> 4800 | BP110: =BL110*100 -> 0 | BQ110: =BM110*300 -> 0 | BR110: =BN110*300 -> 6000 | BS110: 50 | BT110: 0 | BU110: 0 | BV110: 20 | BW110: =BS110*100 -> 5000 | BX110: =BT110*100 -> 0 | BY110: =BU110*300 -> 0 | BZ110: =BV110*300 -> 6000
A111: 3 | B111: Alice Mukabucyana | G111: 30 | H111: 0 | I111: 0 | J111: 10 | K111: =G111*100 -> 3000 | L111: =H111*100 -> 0 | M111: =I111*300 -> 0 | N111: =J111*300 -> 3000 | O111: 32 | P111: 0 | Q111: 0 | R111: 20 | S111: =O111*100 -> 3200 | T111: =P111*100 -> 0 | U111: =Q111*300 -> 0 | V111: =R111*300 -> 6000 | W111: 30 | X111: 0 | Y111: 0 | Z111: 18 | AA111: =W111*100 -> 3000 | AB111: =X111*100 -> 0 | AC111: =Y111*300 -> 0 | AD111: =Z111*300 -> 5400 | AE111: 30 | AF111: 0 | AG111: 0 | AH111: 18 | AI111: =AE111*100 -> 3000 | AJ111: =AF111*100 -> 0 | AK111: =AG111*300 -> 0 | AL111: =AH111*300 -> 5400 | AM111: 34 | AN111: 0 | AO111: 0 | AP111: 18 | AQ111: =AM111*100 -> 3400 | AR111: =AN111*100 -> 0 | AS111: =AO111*300 -> 0 | AT111: =AP111*300 -> 5400 | AU111: 36 | AV111: 0 | AW111: 0 | AX111: 16 | AY111: =AU111*100 -> 3600 | AZ111: =AV111*100 -> 0 | BA111: =AW111*300 -> 0 | BB111: =AX111*300 -> 4800 | BC111: 38 | BD111: 0 | BE111: 0 | BF111: 16 | BG111: =BC111*100 -> 3800 | BH111: =BD111*100 -> 0 | BI111: =BE111*300 -> 0 | BJ111: =BF111*300 -> 4800 | BK111: 41 | BL111: 0 | BM111: 0 | BN111: 18 | BO111: =BK111*100 -> 4100 | BP111: =BL111*100 -> 0 | BQ111: =BM111*300 -> 0 | BR111: =BN111*300 -> 5400 | BS111: 45 | BT111: 0 | BU111: 0 | BV111: 18 | BW111: =BS111*100 -> 4500 | BX111: =BT111*100 -> 0 | BY111: =BU111*300 -> 0 | BZ111: =BV111*300 -> 5400
A112: 4 | B112: Alphonsine Uwimana | G112: 32 | H112: 0 | I112: 0 | J112: 15 | K112: =G112*100 -> 3200 | L112: =H112*100 -> 0 | M112: =I112*300 -> 0 | N112: =J112*300 -> 4500 | O112: 35 | P112: 0 | Q112: 0 | R112: 20 | S112: =O112*100 -> 3500 | T112: =P112*100 -> 0 | U112: =Q112*300 -> 0 | V112: =R112*300 -> 6000 | W112: 35 | X112: 0 | Y112: 0 | Z112: 16 | AA112: =W112*100 -> 3500 | AB112: =X112*100 -> 0 | AC112: =Y112*300 -> 0 | AD112: =Z112*300 -> 4800 | AE112: 36 | AF112: 0 | AG112: 0 | AH112: 12 | AI112: =AE112*100 -> 3600 | AJ112: =AF112*100 -> 0 | AK112: =AG112*300 -> 0 | AL112: =AH112*300 -> 3600 | AM112: 40 | AN112: 0 | AO112: 0 | AP112: 12 | AQ112: =AM112*100 -> 4000 | AR112: =AN112*100 -> 0 | AS112: =AO112*300 -> 0 | AT112: =AP112*300 -> 3600 | AU112: 42 | AV112: 0 | AW112: 0 | AX112: 12 | AY112: =AU112*100 -> 4200 | AZ112: =AV112*100 -> 0 | BA112: =AW112*300 -> 0 | BB112: =AX112*300 -> 3600 | BC112: 44 | BD112: 0 | BE112: 0 | BF112: 20 | BG112: =BC112*100 -> 4400 | BH112: =BD112*100 -> 0 | BI112: =BE112*300 -> 0 | BJ112: =BF112*300 -> 6000 | BK112: 45 | BL112: 0 | BM112: 0 | BN112: 20 | BO112: =BK112*100 -> 4500 | BP112: =BL112*100 -> 0 | BQ112: =BM112*300 -> 0 | BR112: =BN112*300 -> 6000 | BS112: 48 | BT112: 0 | BU112: 0 | BV112: 20 | BW112: =BS112*100 -> 4800 | BX112: =BT112*100 -> 0 | BY112: =BU112*300 -> 0 | BZ112: =BV112*300 -> 6000
A113: 5 | B113: Angelique Mukaburasa | G113: 50 | H113: 0 | I113: 0 | J113: 12 | K113: =G113*100 -> 5000 | L113: =H113*100 -> 0 | M113: =I113*300 -> 0 | N113: =J113*300 -> 3600 | O113: 50 | P113: 0 | Q113: 0 | R113: 12 | S113: =O113*100 -> 5000 | T113: =P113*100 -> 0 | U113: =Q113*300 -> 0 | V113: =R113*300 -> 3600 | W113: 52 | X113: 0 | Y113: 0 | Z113: 14 | AA113: =W113*100 -> 5200 | AB113: =X113*100 -> 0 | AC113: =Y113*300 -> 0 | AD113: =Z113*300 -> 4200 | AE113: 50 | AF113: 0 | AG113: 0 | AH113: 16 | AI113: =AE113*100 -> 5000 | AJ113: =AF113*100 -> 0 | AK113: =AG113*300 -> 0 | AL113: =AH113*300 -> 4800 | AM113: 52 | AN113: 0 | AO113: 0 | AP113: 18 | AQ113: =AM113*100 -> 5200 | AR113: =AN113*100 -> 0 | AS113: =AO113*300 -> 0 | AT113: =AP113*300 -> 5400 | AU113: 52 | AV113: 0 | AW113: 0 | AX113: 18 | AY113: =AU113*100 -> 5200 | AZ113: =AV113*100 -> 0 | BA113: =AW113*300 -> 0 | BB113: =AX113*300 -> 5400 | BC113: 56 | BD113: 0 | BE113: 0 | BF113: 18 | BG113: =BC113*100 -> 5600 | BH113: =BD113*100 -> 0 | BI113: =BE113*300 -> 0 | BJ113: =BF113*300 -> 5400 | BK113: 56 | BL113: 0 | BM113: 0 | BN113: 18 | BO113: =BK113*100 -> 5600 | BP113: =BL113*100 -> 0 | BQ113: =BM113*300 -> 0 | BR113: =BN113*300 -> 5400 | BS113: 55 | BT113: 0 | BU113: 0 | BV113: 18 | BW113: =BS113*100 -> 5500 | BX113: =BT113*100 -> 0 | BY113: =BU113*300 -> 0 | BZ113: =BV113*300 -> 5400
...

Sheet Baseline (June to Sep)
G2: June | M2: July | S2: August | Y2: September
A3: # | B3: Member | C3: Coop name | D3: Number of people in the household | E3: Monthly household income | F3: Number of meals per person per day | G3: Firewood consumption foraged (kg/month) | H3: Firewood consumption bought(kg/month) | I3: Charcoal consumption (kg/month) | J3: Cost of firewood in-kind (RWF/month) | K3: Cost of firewood spent (RWF/month) | L3: Cost of charcoal (RWF/month) | M3: Firewood consumption foraged (kg/month) | N3: Firewood consumption bought(kg/month) | O3: Charcoal consumption (kg/month) | P3: Cost of firewood in-kind (RWF/month) | Q3: Cost of firewood spent (RWF/month) | R3: Cost of charcoal (RWF/month) | S3: Firewood consumption foraged (kg/month) | T3: Firewood consumption bought(kg/month) | U3: Charcoal consumption (kg/month) | V3: Cost of firewood in-kind (RWF/month) | W3: Cost of firewood spent (RWF/month) | X3: Cost of charcoal (RWF/month) | Y3: Firewood consumption foraged (kg/month) | Z3: Firewood consumption bought(kg/month) | AA3: Charcoal consumption (kg/month) | AB3: Cost of firewood in-kind (RWF/month) | AC3: Cost of firewood spent (RWF/month) | AD3: Cost of charcoal (RWF/month)
A4: 1 | B4: Agnes MUSABYEYEZU | C4: Twiyubake Family | D4: 8 | E4: 45000 | F4: 2 | G4: 40 | I4: 20 | K4: =G4*100 -> 4000 | L4: =I4*300 -> 6000 | M4: 20 | O4: 22 | Q4: =M4*100 -> 2000 | R4: =O4*300 -> 6600 | S4: 40 | U4: 15 | V4: =S4*100 -> 4000 | X4: =U4*300 -> 4500 | Y4: 20 | AA4: 22 | AC4: =Y4*100 -> 2000 | AD4: =AA4*300 -> 6600
A5: 2 | B5: Alice MUKAMISHA | C5: Genda ugire utyo | D5: 7 | E5: 50000 | F5: 3 | G5: 20 | I5: 40 | K5: =G5*100 -> 2000 | L5: =I5*300 -> 12000 | M5: 0 | O5: 35 | Q5: =M5*100 -> 0 | R5: =O5*300 -> 10500 | S5: 20 | U5: 25 | V5: =S5*100 -> 2000 | X5: =U5*300 -> 7500 | Y5: 32 | AA5: 30 | AC5: =Y5*100 -> 3200 | AD5: =AA5*300 -> 9000
A6: 3 | B6: Alphonsine MUKARUGINA | C6: Twisungane | D6: 10 | E6: 50000 | F6: 3 | G6: 60 | I6: 30 | K6: =G6*100 -> 6000 | L6: =I6*300 -> 9000 | M6: 30 | O6: 28 | Q6: =M6*100 -> 3000 | R6: =O6*300 -> 8400 | S6: 35 | U6: 22 | V6: =S6*100 -> 3500 | X6: =U6*300 -> 6600 | Y6: 38 | AA6: 25 | AC6: =Y6*100 -> 3800 | AD6: =AA6*300 -> 7500
A7: 4 | B7: Anathalia MUKANKUSI | C7: Genda ugire utyo | D7: 7 | E7: 25000 | F7: 2 | G7: 20 | I7: 0 | K7: =G7*100 -> 2000 | L7: =I7*300 -> 0 | M7: 20 | O7: 10 | Q7: =M7*100 -> 2000 | R7: =O7*300 -> 3000 | S7: 25 | U7: 10 | V7: =S7*100 -> 2500 | X7: =U7*300 -> 3000 | Y7: 25 | AA7: 14 | AC7: =Y7*100 -> 2500 | AD7: =AA7*300 -> 4200
A8: 5 | B8: Angelique BYUKUSENGE | C8: Abagarukanarumuri | D8: 4 | E8: 45000 | F8: 2 | G8: 40 | I8: 0 | K8: =G8*100 -> 4000 | L8: =I8*300 -> 0 | M8: 10 | O8: 15 | Q8: =M8*100 -> 1000 | R8: =O8*300 -> 4500 | S8: 20 | U8: 10 | V8: =S8*100 -> 2000 | X8: =U8*300 -> 3000 | Y8: 30 | AA8: 15 | AC8: =Y8*100 -> 3000 | AD8: =AA8*300 -> 4500
A9: 6 | B9: Angelique MUHAWENIMANA | C9: Icyerekezo | D9: 3 | E9: 30000 | F9: 2 | G9: 20 | I9: 20 | K9: =G9*100 -> 2000 | L9: =I9*300 -> 6000 | M9: 20 | O9: 10 | Q9: =M9*100 -> 2000 | R9: =O9*300 -> 3000 | S9: 40 | U9: 5 | V9: =S9*100 -> 4000 | X9: =U9*300 -> 1500 | Y9: 32 | AA9: 10 | AC9: =Y9*100 -> 3200 | AD9: =AA9*300 -> 3000
A10: 7 | B10: Angelique MUKANDORI | C10: Twisungane | D10: 6 | E10: 55000 | F10: 3 | G10: 60 | I10: 40 | K10: =G10*100 -> 6000 | L10: =I10*300 -> 12000 | M10: 40 | O10: 40 | Q10: =M10*100 -> 4000 | R10: =O10*300 -> 12000 | S10: 40 | U10: 34 | V10: =S10*100 -> 4000 | X10: =U10*300 -> 10200 | Y10: 25 | AA10: 30 | AC10: =Y10*100 -> 2500 | AD10: =AA10*300 -> 9000
A11: 8 | B11: Angelique NYIRANEZA | C11: Genda ugire utyo | D11: 9 | E11: 60000 | F11: 3 | G11: 40 | I11: 40 | K11: =G11*100 -> 4000 | L11: =I11*300 -> 12000 | M11: 20 | O11: 40 | Q11: =M11*100 -> 2000 | R11: =O11*300 -> 12000 | S11: 40 | U11: 35 | V11: =S11*100 -> 4000 | X11: =U11*300 -> 10500 | Y11: 45 | AA11: 30 | AC11: =Y11*100 -> 4500 | AD11: =AA11*300 -> 9000
A12: 9 | B12: Anitha GATESI | C12: Abagarukanarumuri | D12: 4 | E12: 30000 | F12: 2 | G12: 0 | I12: 60 | K12: =G12*100 -> 0 | L12: =I12*300 -> 18000 | M12: 10 | O12: 40 | Q12: =M12*100 -> 1000 | R12: =O12*300 -> 12000 | S12: 0 | U12: 40 | V12: =S12*100 -> 0 | X12: =U12*300 -> 12000 | Y12: 15 | AA12: 37 | AC12: =Y12*100 -> 1500 | AD12: =AA12*300 -> 11100
A13: 10 | B13: Athanasie MUKAGASHUGI | C13: Twisungane | D13: 6 | E13: 60000 | F13: 3 | G13: 20 | I13: 50 | K13: =G13*100 -> 2000 | L13: =I13*300 -> 15000 | M13: 20 | O13: 38 | Q13: =M13*100 -> 2000 | R13: =O13*300 -> 11400 | S13: 26 | U13: 35 | V13: =S13*100 -> 2600 | X13: =U13*300 -> 10500 | Y13: 15 | AA13: 38 | AC13: =Y13*100 -> 1500 | AD13: =AA13*300 -> 11400
A14: 11 | B14: Augustin NGIRABATWARE | C14: Ruganeheza | D14: 4 | E14: 30000 | F14: 2 | G14: 80 | I14: 0 | K14: =G14*100 -> 8000 | L14: =I14*300 -> 0 | M14: 55 | O14: 10 | Q14: =M14*100 -> 5500 | R14: =O14*300 -> 3000 | S14: 35 | U14: 15 | V14: =S14*100 -> 3500 | X14: =U14*300 -> 4500 | Y14: 25 | AA14: 22 | AC14: =Y14*100 -> 2500 | AD14: =AA14*300 -> 6600
A15: 12 | B15: Beatrice MUHORAKEYE | C15: Ruganeheza | D15: 6 | E15: 55000 | F15: 3 | G15: 20 | I15: 40 | K15: =G15*100 -> 2000 | L15: =I15*300 -> 12000 | M15: 20 | O15: 35 | Q15: =M15*100 -> 2000 | R15: =O15*300 -> 10500 | S15: 10 | U15: 30 | V15: =S15*100 -> 1000 | X15: =U15*300 -> 9000 | Y15: 10 | AA15: 25 | AC15: =Y15*100 -> 1000 | AD15: =AA15*300 -> 7500
